Workbook

Sheet Raw Logs
A1: Buttons: (2,3,4,5,6,7,8) (0,1,2,3,7) (1,2,3,4,8) (1,2,3,4,5,6,8) (0,4,6,7,8) (4,6,7) (5) (0,1,3,7,8) | E1: =IF(LEFT(A1,7)="SOLVED!",1,"")
A2: Third segment: {13,30,32,41,36,25,29,24,45} | E2: =IF(LEFT(A2,7)="SOLVED!",1,"")
A3: SOLVED! New button count: 45 for line 0 (Time: 0.07 seconds) | E3: =IF(LEFT(A3,7)="SOLVED!",1,"") -> 1 | F3: =IF(E3=1,RIGHT(A3,LEN(A3)-26),"") -> 45 for line 0 (Time: 0.07 seconds) | G3: =IF(E3=1,LEFT(F3,SEARCH(" ",F3))*1,"") -> 45 | H3: =IF(E3=1,MID(F3,SEARCH("line ",F3)+5,SEARCH(" ",F3,SEARCH("line ",F3)+6)-SEARCH("line ",F3)-5)*1,"") -> 0 | I3: =IF(E3=1,MID(F3,SEARCH("Time: ",F3)+6,SEARCH(" ",F3,SEARCH("Time: ",F3)+7)-SEARCH("Time: ",F3)-6)*1,"") -> 0.07
A4: Buttons: (0,3,4,5) (3,4) (0,1,3,5,6) (0,1,5,6) (5,6) (0,1,2,4,6) (1,2,3,5) (2,4,5,6) (0,1,2,3,6) | E4: =IF(LEFT(A4,7)="SOLVED!",1,"") | F4: =IF(E4=1,RIGHT(A4,LEN(A4)-26),"") | G4: =IF(E4=1,LEFT(F4,SEARCH(" ",F4))*1,"") | H4: =IF(E4=1,MID(F4,SEARCH("line ",F4)+5,SEARCH(" ",F4,SEARCH("line ",F4)+6)-SEARCH("line ",F4)-5)*1,"") | I4: =IF(E4=1,MID(F4,SEARCH("Time: ",F4)+6,SEARCH(" ",F4,SEARCH("Time: ",F4)+7)-SEARCH("Time: ",F4)-6)*1,"")
A5: Third segment: {54,55,37,35,27,43,65} | E5: =IF(LEFT(A5,7)="SOLVED!",1,"") | F5: =IF(E5=1,RIGHT(A5,LEN(A5)-26),"") | G5: =IF(E5=1,LEFT(F5,SEARCH(" ",F5))*1,"") | H5: =IF(E5=1,MID(F5,SEARCH("line ",F5)+5,SEARCH(" ",F5,SEARCH("line ",F5)+6)-SEARCH("line ",F5)-5)*1,"") | I5: =IF(E5=1,MID(F5,SEARCH("Time: ",F5)+6,SEARCH(" ",F5,SEARCH("Time: ",F5)+7)-SEARCH("Time: ",F5)-6)*1,"")
A6: SOLVED! New button count: 68 for line 1 (Time: 2.23 seconds) | E6: =IF(LEFT(A6,7)="SOLVED!",1,"") -> 1 | F6: =IF(E6=1,RIGHT(A6,LEN(A6)-26),"") -> 68 for line 1 (Time: 2.23 seconds) | G6: =IF(E6=1,LEFT(F6,SEARCH(" ",F6))*1,"") -> 68 | H6: =IF(E6=1,MID(F6,SEARCH("line ",F6)+5,SEARCH(" ",F6,SEARCH("line ",F6)+6)-SEARCH("line ",F6)-5)*1,"") -> 1 | I6: =IF(E6=1,MID(F6,SEARCH("Time: ",F6)+6,SEARCH(" ",F6,SEARCH("Time: ",F6)+7)-SEARCH("Time: ",F6)-6)*1,"") -> 2.23
A7: Buttons: (1,3) (1,2) (0,1,2,3) | E7: =IF(LEFT(A7,7)="SOLVED!",1,"") | F7: =IF(E7=1,RIGHT(A7,LEN(A7)-26),"") | G7: =IF(E7=1,LEFT(F7,SEARCH(" ",F7))*1,"") | H7: =IF(E7=1,MID(F7,SEARCH("line ",F7)+5,SEARCH(" ",F7,SEARCH("line ",F7)+6)-SEARCH("line ",F7)-5)*1,"") | I7: =IF(E7=1,MID(F7,SEARCH("Time: ",F7)+6,SEARCH(" ",F7,SEARCH("Time: ",F7)+7)-SEARCH("Time: ",F7)-6)*1,"")
A8: Third segment: {19,46,28,37} | E8: =IF(LEFT(A8,7)="SOLVED!",1,"") | F8: =IF(E8=1,RIGHT(A8,LEN(A8)-26),"") | G8: =IF(E8=1,LEFT(F8,SEARCH(" ",F8))*1,"") | H8: =IF(E8=1,MID(F8,SEARCH("line ",F8)+5,SEARCH(" ",F8,SEARCH("line ",F8)+6)-SEARCH("line ",F8)-5)*1,"") | I8: =IF(E8=1,MID(F8,SEARCH("Time: ",F8)+6,SEARCH(" ",F8,SEARCH("Time: ",F8)+7)-SEARCH("Time: ",F8)-6)*1,"")
A9: SOLVED! New button count: 46 for line 2 (Time: 0.0 seconds) | E9: =IF(LEFT(A9,7)="SOLVED!",1,"") -> 1 | F9: =IF(E9=1,RIGHT(A9,LEN(A9)-26),"") -> 46 for line 2 (Time: 0.0 seconds) | G9: =IF(E9=1,LEFT(F9,SEARCH(" ",F9))*1,"") -> 46 | H9: =IF(E9=1,MID(F9,SEARCH("line ",F9)+5,SEARCH(" ",F9,SEARCH("line ",F9)+6)-SEARCH("line ",F9)-5)*1,"") -> 2 | I9: =IF(E9=1,MID(F9,SEARCH("Time: ",F9)+6,SEARCH(" ",F9,SEARCH("Time: ",F9)+7)-SEARCH("Time: ",F9)-6)*1,"") -> 0
A10: Buttons: (2,3) (0,5) (0,3) (1,3,5) (1,3) (1,2,3) (0,2,3,4) (0,1,3) | E10: =IF(LEFT(A10,7)="SOLVED!",1,"") | F10: =IF(E10=1,RIGHT(A10,LEN(A10)-26),"") | G10: =IF(E10=1,LEFT(F10,SEARCH(" ",F10))*1,"") | H10: =IF(E10=1,MID(F10,SEARCH("line ",F10)+5,SEARCH(" ",F10,SEARCH("line ",F10)+6)-SEARCH("line ",F10)-5)*1,"") | I10: =IF(E10=1,MID(F10,SEARCH("Time: ",F10)+6,SEARCH(" ",F10,SEARCH("Time: ",F10)+7)-SEARCH("Time: ",F10)-6)*1,"")
A11: Third segment: {43,26,17,46,15,25} | E11: =IF(LEFT(A11,7)="SOLVED!",1,"") | F11: =IF(E11=1,RIGHT(A11,LEN(A11)-26),"") | G11: =IF(E11=1,LEFT(F11,SEARCH(" ",F11))*1,"") | H11: =IF(E11=1,MID(F11,SEARCH("line ",F11)+5,SEARCH(" ",F11,SEARCH("line ",F11)+6)-SEARCH("line ",F11)-5)*1,"") | I11: =IF(E11=1,MID(F11,SEARCH("Time: ",F11)+6,SEARCH(" ",F11,SEARCH("Time: ",F11)+7)-SEARCH("Time: ",F11)-6)*1,"")
A12: SOLVED! New button count: 58 for line 3 (Time: 0.01 seconds) | E12: =IF(LEFT(A12,7)="SOLVED!",1,"") -> 1 | F12: =IF(E12=1,RIGHT(A12,LEN(A12)-26),"") -> 58 for line 3 (Time: 0.01 seconds) | G12: =IF(E12=1,LEFT(F12,SEARCH(" ",F12))*1,"") -> 58 | H12: =IF(E12=1,MID(F12,SEARCH("line ",F12)+5,SEARCH(" ",F12,SEARCH("line ",F12)+6)-SEARCH("line ",F12)-5)*1,"") -> 3 | I12: =IF(E12=1,MID(F12,SEARCH("Time: ",F12)+6,SEARCH(" ",F12,SEARCH("Time: ",F12)+7)-SEARCH("Time: ",F12)-6)*1,"") -> 0.01
A13: Buttons: (0,1,2,3,5,7,8) (0,1,2,3,4,6,7,8) (1) (0,2,3,4,5,6,7) (0,1,7) (0,2,3,5) (3,8) (1,6) (0,1,2,4) (0,1,6,7,8) | E13: =IF(LEFT(A13,7)="SOLVED!",1,"") | F13: =IF(E13=1,RIGHT(A13,LEN(A13)-26),"") | G13: =IF(E13=1,LEFT(F13,SEARCH(" ",F13))*1,"") | H13: =IF(E13=1,MID(F13,SEARCH("line ",F13)+5,SEARCH(" ",F13,SEARCH("line ",F13)+6)-SEARCH("line ",F13)-5)*1,"") | I13: =IF(E13=1,MID(F13,SEARCH("Time: ",F13)+6,SEARCH(" ",F13,SEARCH("Time: ",F13)+7)-SEARCH("Time: ",F13)-6)*1,"")
A14: Third segment: {61,67,34,31,28,23,53,50,24} | E14: =IF(LEFT(A14,7)="SOLVED!",1,"") | F14: =IF(E14=1,RIGHT(A14,LEN(A14)-26),"") | G14: =IF(E14=1,LEFT(F14,SEARCH(" ",F14))*1,"") | H14: =IF(E14=1,MID(F14,SEARCH("line ",F14)+5,SEARCH(" ",F14,SEARCH("line ",F14)+6)-SEARCH("line ",F14)-5)*1,"") | I14: =IF(E14=1,MID(F14,SEARCH("Time: ",F14)+6,SEARCH(" ",F14,SEARCH("Time: ",F14)+7)-SEARCH("Time: ",F14)-6)*1,"")
... A305: from run.rb:19:in `<main>' | E305: =IF(LEFT(A305,7)="SOLVED!",1,"") | F305: =IF(E305=1,RIGHT(A305,LEN(A305)-26),"") | G305: =IF(E305=1,LEFT(F305,SEARCH(" ",F305))*1,"") | H305: =IF(E305=1,MID(F305,SEARCH("line ",F305)+5,SEARCH(" ",F305,SEARCH("line ",F305)+6)-SEARCH("line ",F305)-5)*1,"") | I305: =IF(E305=1,MID(F305,SEARCH("Time: ",F305)+6,SEARCH(" ",F305,SEARCH("Time: ",F305)+7)-SEARCH("Time: ",F305)-6)*1,"")
E306: =IF(LEFT(A306,7)="SOLVED!",1,"") | F306: =IF(E306=1,RIGHT(A306,LEN(A306)-26),"") | G306: =IF(E306=1,LEFT(F306,SEARCH(" ",F306))*1,"") | H306: =IF(E306=1,MID(F306,SEARCH("line ",F306)+5,SEARCH(" ",F306,SEARCH("line ",F306)+6)-SEARCH("line ",F306)-5)*1,"") | I306: =IF(E306=1,MID(F306,SEARCH("Time: ",F306)+6,SEARCH(" ",F306,SEARCH("Time: ",F306)+7)-SEARCH("Time: ",F306)-6)*1,"")
A307: [~/Documents/programming/adventofcode/2025] | E307: =IF(LEFT(A307,7)="SOLVED!",1,"") | F307: =IF(E307=1,RIGHT(A307,LEN(A307)-26),"") | G307: =IF(E307=1,LEFT(F307,SEARCH(" ",F307))*1,"") | H307: =IF(E307=1,MID(F307,SEARCH("line ",F307)+5,SEARCH(" ",F307,SEARCH("line ",F307)+6)-SEARCH("line ",F307)-5)*1,"") | I307: =IF(E307=1,MID(F307,SEARCH("Time: ",F307)+6,SEARCH(" ",F307,SEARCH("Time: ",F307)+7)-SEARCH("Time: ",F307)-6)*1,"")
A308: 19:02 - gregeusden-> ruby run.rb 10 2 | E308: =IF(LEFT(A308,7)="SOLVED!",1,"") | F308: =IF(E308=1,RIGHT(A308,LEN(A308)-26),"") | G308: =IF(E308=1,LEFT(F308,SEARCH(" ",F308))*1,"") | H308: =IF(E308=1,MID(F308,SEARCH("line ",F308)+5,SEARCH(" ",F308,SEARCH("line ",F308)+6)-SEARCH("line ",F308)-5)*1,"") | I308: =IF(E308=1,MID(F308,SEARCH("Time: ",F308)+6,SEARCH(" ",F308,SEARCH("Time: ",F308)+7)-SEARCH("Time: ",F308)-6)*1,"")
A309: Buttons: (0,2) (0,2,3,4) (0,1,4) (0,1,2) (0,4) (0,1) (2,3) | E309: =IF(LEFT(A309,7)="SOLVED!",1,"") | F309: =IF(E309=1,RIGHT(A309,LEN(A309)-26),"") | G309: =IF(E309=1,LEFT(F309,SEARCH(" ",F309))*1,"") | H309: =IF(E309=1,MID(F309,SEARCH("line ",F309)+5,SEARCH(" ",F309,SEARCH("line ",F309)+6)-SEARCH("line ",F309)-5)*1,"") | I309: =IF(E309=1,MID(F309,SEARCH("Time: ",F309)+6,SEARCH(" ",F309,SEARCH("Time: ",F309)+7)-SEARCH("Time: ",F309)-6)*1,"")
A310: Third segment: {48,21,44,21,23} | E310: =IF(LEFT(A310,7)="SOLVED!",1,"") | F310: =IF(E310=1,RIGHT(A310,LEN(A310)-26),"") | G310: =IF(E310=1,LEFT(F310,SEARCH(" ",F310))*1,"") | H310: =IF(E310=1,MID(F310,SEARCH("line ",F310)+5,SEARCH(" ",F310,SEARCH("line ",F310)+6)-SEARCH("line ",F310)-5)*1,"") | I310: =IF(E310=1,MID(F310,SEARCH("Time: ",F310)+6,SEARCH(" ",F310,SEARCH("Time: ",F310)+7)-SEARCH("Time: ",F310)-6)*1,"")
A311: SOLVED! New button count: 48 for line 96 (Time: 0.03 seconds) | E311: =IF(LEFT(A311,7)="SOLVED!",1,"") -> 1 | F311: =IF(E311=1,RIGHT(A311,LEN(A311)-26),"") -> 48 for line 96 (Time: 0.03 seconds) | G311: =IF(E311=1,LEFT(F311,SEARCH(" ",F311))*1,"") -> 48 | H311: =IF(E311=1,MID(F311,SEARCH("line ",F311)+5,SEARCH(" ",F311,SEARCH("line ",F311)+6)-SEARCH("line ",F311)-5)*1,"") -> 96 | I311: =IF(E311=1,MID(F311,SEARCH("Time: ",F311)+6,SEARCH(" ",F311,SEARCH("Time: ",F311)+7)-SEARCH("Time: ",F311)-6)*1,"") -> 0.03
A312: Buttons: (5,6,7) (1,2,3,5,6) (2,3,4,6) (1,2,3,5,6,7) (1,6) (0,2,3,4,5,7) (1,2,4,5,6) (1,3,6) (1,6,7) (0,2,4,5) | E312: =IF(LEFT(A312,7)="SOLVED!",1,"") | F312: =IF(E312=1,RIGHT(A312,LEN(A312)-26),"") | G312: =IF(E312=1,LEFT(F312,SEARCH(" ",F312))*1,"") | H312: =IF(E312=1,MID(F312,SEARCH("line ",F312)+5,SEARCH(" ",F312,SEARCH("line ",F312)+6)-SEARCH("line ",F312)-5)*1,"") | I312: =IF(E312=1,MID(F312,SEARCH("Time: ",F312)+6,SEARCH(" ",F312,SEARCH("Time: ",F312)+7)-SEARCH("Time: ",F312)-6)*1,"")
A313: Third segment: {20,65,67,45,46,64,76,51} | E313: =IF(LEFT(A313,7)="SOLVED!",1,"") | F313: =IF(E313=1,RIGHT(A313,LEN(A313)-26),"") | G313: =IF(E313=1,LEFT(F313,SEARCH(" ",F313))*1,"") | H313: =IF(E313=1,MID(F313,SEARCH("line ",F313)+5,SEARCH(" ",F313,SEARCH("line ",F313)+6)-SEARCH("line ",F313)-5)*1,"") | I313: =IF(E313=1,MID(F313,SEARCH("Time: ",F313)+6,SEARCH(" ",F313,SEARCH("Time: ",F313)+7)-SEARCH("Time: ",F313)-6)*1,"")
A314: SOLVED! New button count: 96 for line 97 (Time: 0.35 seconds) | E314: =IF(LEFT(A314,7)="SOLVED!",1,"") -> 1 | F314: =IF(E314=1,RIGHT(A314,LEN(A314)-26),"") -> 96 for line 97 (Time: 0.35 seconds) | G314: =IF(E314=1,LEFT(F314,SEARCH(" ",F314))*1,"") -> 96 | H314: =IF(E314=1,MID(F314,SEARCH("line ",F314)+5,SEARCH(" ",F314,SEARCH("line ",F314)+6)-SEARCH("line ",F314)-5)*1,"") -> 97 | I314: =IF(E314=1,MID(F314,SEARCH("Time: ",F314)+6,SEARCH(" ",F314,SEARCH("Time: ",F314)+7)-SEARCH("Time: ",F314)-6)*1,"") -> 0.35
A315: Buttons: (0,1,2,7) (1,2,3,5,6,7,8) (2) (4,6,8) (0,1,3,5,6) (0,2,4,5,6,7) (1,7,8) | E315: =IF(LEFT(A315,7)="SOLVED!",1,"") | F315: =IF(E315=1,RIGHT(A315,LEN(A315)-26),"") | G315: =IF(E315=1,LEFT(F315,SEARCH(" ",F315))*1,"") | H315: =IF(E315=1,MID(F315,SEARCH("line ",F315)+5,SEARCH(" ",F315,SEARCH("line ",F315)+6)-SEARCH("line ",F315)-5)*1,"") | I315: =IF(E315=1,MID(F315,SEARCH("Time: ",F315)+6,SEARCH(" ",F315,SEARCH("Time: ",F315)+7)-SEARCH("Time: ",F315)-6)*1,"")
A316: Third segment: {26,43,32,20,15,24,35,30,32} | E316: =IF(LEFT(A316,7)="SOLVED!",1,"") | F316: =IF(E316=1,RIGHT(A316,LEN(A316)-26),"") | G316: =IF(E316=1,LEFT(F316,SEARCH(" ",F316))*1,"") | H316: =IF(E316=1,MID(F316,SEARCH("line ",F316)+5,SEARCH(" ",F316,SEARCH("line ",F316)+6)-SEARCH("line ",F316)-5)*1,"") | I316: =IF(E316=1,MID(F316,SEARCH("Time: ",F316)+6,SEARCH(" ",F316,SEARCH("Time: ",F316)+7)-SEARCH("Time: ",F316)-6)*1,"")
A317: SOLVED! New button count: 78 for line 98 (Time: 0.0 seconds) | E317: =IF(LEFT(A317,7)="SOLVED!",1,"") -> 1 | F317: =IF(E317=1,RIGHT(A317,LEN(A317)-26),"") -> 78 for line 98 (Time: 0.0 seconds) | G317: =IF(E317=1,LEFT(F317,SEARCH(" ",F317))*1,"") -> 78 | H317: =IF(E317=1,MID(F317,SEARCH("line ",F317)+5,SEARCH(" ",F317,SEARCH("line ",F317)+6)-SEARCH("line ",F317)-5)*1,"") -> 98 | I317: =IF(E317=1,MID(F317,SEARCH("Time: ",F317)+6,SEARCH(" ",F317,SEARCH("Time: ",F317)+7)-SEARCH("Time: ",F317)-6)*1,"") -> 0
A318: Buttons: (0,1,2) (1) (0,1,3) | E318: =IF(LEFT(A318,7)="SOLVED!",1,"") | F318: =IF(E318=1,RIGHT(A318,LEN(A318)-26),"") | G318: =IF(E318=1,LEFT(F318,SEARCH(" ",F318))*1,"") | H318: =IF(E318=1,MID(F318,SEARCH("line ",F318)+5,SEARCH(" ",F318,SEARCH("line ",F318)+6)-SEARCH("line ",F318)-5)*1,"") | I318: =IF(E318=1,MID(F318,SEARCH("Time: ",F318)+6,SEARCH(" ",F318,SEARCH("Time: ",F318)+7)-SEARCH("Time: ",F318)-6)*1,"")
... A353: from run.rb:19:in `<main>' | E353: =IF(LEFT(A353,7)="SOLVED!",1,"") | F353: =IF(E353=1,RIGHT(A353,LEN(A353)-26),"") | G353: =IF(E353=1,LEFT(F353,SEARCH(" ",F353))*1,"") | H353: =IF(E353=1,MID(F353,SEARCH("line ",F353)+5,SEARCH(" ",F353,SEARCH("line ",F353)+6)-SEARCH("line ",F353)-5)*1,"") | I353: =IF(E353=1,MID(F353,SEARCH("Time: ",F353)+6,SEARCH(" ",F353,SEARCH("Time: ",F353)+7)-SEARCH("Time: ",F353)-6)*1,"")
E354: =IF(LEFT(A354,7)="SOLVED!",1,"") | F354: =IF(E354=1,RIGHT(A354,LEN(A354)-26),"") | G354: =IF(E354=1,LEFT(F354,SEARCH(" ",F354))*1,"") | H354: =IF(E354=1,MID(F354,SEARCH("line ",F354)+5,SEARCH(" ",F354,SEARCH("line ",F354)+6)-SEARCH("line ",F354)-5)*1,"") | I354: =IF(E354=1,MID(F354,SEARCH("Time: ",F354)+6,SEARCH(" ",F354,SEARCH("Time: ",F354)+7)-SEARCH("Time: ",F354)-6)*1,"")
A355: [~/Documents/programming/adventofcode/2025] | E355: =IF(LEFT(A355,7)="SOLVED!",1,"") | F355: =IF(E355=1,RIGHT(A355,LEN(A355)-26),"") | G355: =IF(E355=1,LEFT(F355,SEARCH(" ",F355))*1,"") | H355: =IF(E355=1,MID(F355,SEARCH("line ",F355)+5,SEARCH(" ",F355,SEARCH("line ",F355)+6)-SEARCH("line ",F355)-5)*1,"") | I355: =IF(E355=1,MID(F355,SEARCH("Time: ",F355)+6,SEARCH(" ",F355,SEARCH("Time: ",F355)+7)-SEARCH("Time: ",F355)-6)*1,"")
A356: 19:11 - gregeusden-> ruby run.rb 10 2 | E356: =IF(LEFT(A356,7)="SOLVED!",1,"") | F356: =IF(E356=1,RIGHT(A356,LEN(A356)-26),"") | G356: =IF(E356=1,LEFT(F356,SEARCH(" ",F356))*1,"") | H356: =IF(E356=1,MID(F356,SEARCH("line ",F356)+5,SEARCH(" ",F356,SEARCH("line ",F356)+6)-SEARCH("line ",F356)-5)*1,"") | I356: =IF(E356=1,MID(F356,SEARCH("Time: ",F356)+6,SEARCH(" ",F356,SEARCH("Time: ",F356)+7)-SEARCH("Time: ",F356)-6)*1,"")
A357: Buttons: (0,1,3) (1,3) (0,1) (0,1,2) | E357: =IF(LEFT(A357,7)="SOLVED!",1,"") | F357: =IF(E357=1,RIGHT(A357,LEN(A357)-26),"") | G357: =IF(E357=1,LEFT(F357,SEARCH(" ",F357))*1,"") | H357: =IF(E357=1,MID(F357,SEARCH("line ",F357)+5,SEARCH(" ",F357,SEARCH("line ",F357)+6)-SEARCH("line ",F357)-5)*1,"") | I357: =IF(E357=1,MID(F357,SEARCH("Time: ",F357)+6,SEARCH(" ",F357,SEARCH("Time: ",F357)+7)-SEARCH("Time: ",F357)-6)*1,"")
A358: Third segment: {145,147,132,13} | E358: =IF(LEFT(A358,7)="SOLVED!",1,"") | F358: =IF(E358=1,RIGHT(A358,LEN(A358)-26),"") | G358: =IF(E358=1,LEFT(F358,SEARCH(" ",F358))*1,"") | H358: =IF(E358=1,MID(F358,SEARCH("line ",F358)+5,SEARCH(" ",F358,SEARCH("line ",F358)+6)-SEARCH("line ",F358)-5)*1,"") | I358: =IF(E358=1,MID(F358,SEARCH("Time: ",F358)+6,SEARCH(" ",F358,SEARCH("Time: ",F358)+7)-SEARCH("Time: ",F358)-6)*1,"")
A359: SOLVED! New button count: 147 for line 103 (Time: 0.0 seconds) | E359: =IF(LEFT(A359,7)="SOLVED!",1,"") -> 1 | F359: =IF(E359=1,RIGHT(A359,LEN(A359)-26),"") -> 147 for line 103 (Time: 0.0 seconds) | G359: =IF(E359=1,LEFT(F359,SEARCH(" ",F359))*1,"") -> 147 | H359: =IF(E359=1,MID(F359,SEARCH("line ",F359)+5,SEARCH(" ",F359,SEARCH("line ",F359)+6)-SEARCH("line ",F359)-5)*1,"") -> 103 | I359: =IF(E359=1,MID(F359,SEARCH("Time: ",F359)+6,SEARCH(" ",F359,SEARCH("Time: ",F359)+7)-SEARCH("Time: ",F359)-6)*1,"") -> 0
A360: Buttons: (0,1,3,5,6,7) (1,2,3,6) (1,4) (0,2,3,6,7) (5,6) (1,2,4,7) | E360: =IF(LEFT(A360,7)="SOLVED!",1,"") | F360: =IF(E360=1,RIGHT(A360,LEN(A360)-26),"") | G360: =IF(E360=1,LEFT(F360,SEARCH(" ",F360))*1,"") | H360: =IF(E360=1,MID(F360,SEARCH("line ",F360)+5,SEARCH(" ",F360,SEARCH("line ",F360)+6)-SEARCH("line ",F360)-5)*1,"") | I360: =IF(E360=1,MID(F360,SEARCH("Time: ",F360)+6,SEARCH(" ",F360,SEARCH("Time: ",F360)+7)-SEARCH("Time: ",F360)-6)*1,"")
A361: Third segment: {24,60,50,39,36,19,49,44} | E361: =IF(LEFT(A361,7)="SOLVED!",1,"") | F361: =IF(E361=1,RIGHT(A361,LEN(A361)-26),"") | G361: =IF(E361=1,LEFT(F361,SEARCH(" ",F361))*1,"") | H361: =IF(E361=1,MID(F361,SEARCH("line ",F361)+5,SEARCH(" ",F361,SEARCH("line ",F361)+6)-SEARCH("line ",F361)-5)*1,"") | I361: =IF(E361=1,MID(F361,SEARCH("Time: ",F361)+6,SEARCH(" ",F361,SEARCH("Time: ",F361)+7)-SEARCH("Time: ",F361)-6)*1,"")
A362: SOLVED! New button count: 85 for line 104 (Time: 0.0 seconds) | E362: =IF(LEFT(A362,7)="SOLVED!",1,"") -> 1 | F362: =IF(E362=1,RIGHT(A362,LEN(A362)-26),"") -> 85 for line 104 (Time: 0.0 seconds) | G362: =IF(E362=1,LEFT(F362,SEARCH(" ",F362))*1,"") -> 85 | H362: =IF(E362=1,MID(F362,SEARCH("line ",F362)+5,SEARCH(" ",F362,SEARCH("line ",F362)+6)-SEARCH("line ",F362)-5)*1,"") -> 104 | I362: =IF(E362=1,MID(F362,SEARCH("Time: ",F362)+6,SEARCH(" ",F362,SEARCH("Time: ",F362)+7)-SEARCH("Time: ",F362)-6)*1,"") -> 0
A363: Buttons: (0,1,2,3,4,6,8) (4,5) (3,6,8) (6,7,8) (2,3) (3,4,5,6,8) (0,2,5,7,8) (4,5,7) (0,1,6) | E363: =IF(LEFT(A363,7)="SOLVED!",1,"") | F363: =IF(E363=1,RIGHT(A363,LEN(A363)-26),"") | G363: =IF(E363=1,LEFT(F363,SEARCH(" ",F363))*1,"") | H363: =IF(E363=1,MID(F363,SEARCH("line ",F363)+5,SEARCH(" ",F363,SEARCH("line ",F363)+6)-SEARCH("line ",F363)-5)*1,"") | I363: =IF(E363=1,MID(F363,SEARCH("Time: ",F363)+6,SEARCH(" ",F363,SEARCH("Time: ",F363)+7)-SEARCH("Time: ",F363)-6)*1,"")
A364: Third segment: {27,20,38,50,38,31,41,9,42} | E364: =IF(LEFT(A364,7)="SOLVED!",1,"") | F364: =IF(E364=1,RIGHT(A364,LEN(A364)-26),"") | G364: =IF(E364=1,LEFT(F364,SEARCH(" ",F364))*1,"") | H364: =IF(E364=1,MID(F364,SEARCH("line ",F364)+5,SEARCH(" ",F364,SEARCH("line ",F364)+6)-SEARCH("line ",F364)-5)*1,"") | I364: =IF(E364=1,MID(F364,SEARCH("Time: ",F364)+6,SEARCH(" ",F364,SEARCH("Time: ",F364)+7)-SEARCH("Time: ",F364)-6)*1,"")
...

Sheet Raw Logs - Python
A1: Buttons: (2,3,4,5,6,7,8) (0,1,2,3,7) (1,2,3,4,8) (1,2,3,4,5,6,8) (0,4,6,7,8) (4,6,7) (5) (0,1,3,7,8) | E1: =IF(LEFT(A1,7)="SOLVED!",1,"")
A2: Third segment: {13,30,32,41,36,25,29,24,45} | E2: =IF(LEFT(A2,7)="SOLVED!",1,"")
E3: =IF(LEFT(A3,7)="SOLVED!",1,"") | F3: =IF(E3=1,RIGHT(A3,LEN(A3)-26),"") | G3: =IF(E3=1,LEFT(F3,SEARCH(" ",F3))*1,"") | H3: =IF(E3=1,MID(F3,SEARCH("line ",F3)+5,SEARCH(" ",F3,SEARCH("line ",F3)+6)-SEARCH("line ",F3)-5)*1,"") | I3: =IF(E3=1,MID(F3,SEARCH("Time: ",F3)+6,SEARCH(" ",F3,SEARCH("Time: ",F3)+7)-SEARCH("Time: ",F3)-6)*1,"")
A4: SOLVED! New button count: 45.0 for line 0 (Time: 0.0009748935699462891 seconds) | E4: =IF(LEFT(A4,7)="SOLVED!",1,"") -> 1 | F4: =IF(E4=1,RIGHT(A4,LEN(A4)-26),"") -> 45.0 for line 0 (Time: 0.0009748935699462891 seconds) | G4: =IF(E4=1,LEFT(F4,SEARCH(" ",F4))*1,"") -> 45 | H4: =IF(E4=1,MID(F4,SEARCH("line ",F4)+5,SEARCH(" ",F4,SEARCH("line ",F4)+6)-SEARCH("line ",F4)-5)*1,"") -> 0 | I4: =IF(E4=1,MID(F4,SEARCH("Time: ",F4)+6,SEARCH(" ",F4,SEARCH("Time: ",F4)+7)-SEARCH("Time: ",F4)-6)*1,"") -> 0.00097489357
A5: Buttons: (0,3,4,5) (3,4) (0,1,3,5,6) (0,1,5,6) (5,6) (0,1,2,4,6) (1,2,3,5) (2,4,5,6) (0,1,2,3,6) | E5: =IF(LEFT(A5,7)="SOLVED!",1,"") | F5: =IF(E5=1,RIGHT(A5,LEN(A5)-26),"") | G5: =IF(E5=1,LEFT(F5,SEARCH(" ",F5))*1,"") | H5: =IF(E5=1,MID(F5,SEARCH("line ",F5)+5,SEARCH(" ",F5,SEARCH("line ",F5)+6)-SEARCH("line ",F5)-5)*1,"") | I5: =IF(E5=1,MID(F5,SEARCH("Time: ",F5)+6,SEARCH(" ",F5,SEARCH("Time: ",F5)+7)-SEARCH("Time: ",F5)-6)*1,"")
A6: Third segment: {54,55,37,35,27,43,65} | E6: =IF(LEFT(A6,7)="SOLVED!",1,"") | F6: =IF(E6=1,RIGHT(A6,LEN(A6)-26),"") | G6: =IF(E6=1,LEFT(F6,SEARCH(" ",F6))*1,"") | H6: =IF(E6=1,MID(F6,SEARCH("line ",F6)+5,SEARCH(" ",F6,SEARCH("line ",F6)+6)-SEARCH("line ",F6)-5)*1,"") | I6: =IF(E6=1,MID(F6,SEARCH("Time: ",F6)+6,SEARCH(" ",F6,SEARCH("Time: ",F6)+7)-SEARCH("Time: ",F6)-6)*1,"")
E7: =IF(LEFT(A7,7)="SOLVED!",1,"") | F7: =IF(E7=1,RIGHT(A7,LEN(A7)-26),"") | G7: =IF(E7=1,LEFT(F7,SEARCH(" ",F7))*1,"") | H7: =IF(E7=1,MID(F7,SEARCH("line ",F7)+5,SEARCH(" ",F7,SEARCH("line ",F7)+6)-SEARCH("line ",F7)-5)*1,"") | I7: =IF(E7=1,MID(F7,SEARCH("Time: ",F7)+6,SEARCH(" ",F7,SEARCH("Time: ",F7)+7)-SEARCH("Time: ",F7)-6)*1,"")
A8: SOLVED! New button count: 68.0 for line 1 (Time: 0.0009710788726806641 seconds) | E8: =IF(LEFT(A8,7)="SOLVED!",1,"") -> 1 | F8: =IF(E8=1,RIGHT(A8,LEN(A8)-26),"") -> 68.0 for line 1 (Time: 0.0009710788726806641 seconds) | G8: =IF(E8=1,LEFT(F8,SEARCH(" ",F8))*1,"") -> 68 | H8: =IF(E8=1,MID(F8,SEARCH("line ",F8)+5,SEARCH(" ",F8,SEARCH("line ",F8)+6)-SEARCH("line ",F8)-5)*1,"") -> 1 | I8: =IF(E8=1,MID(F8,SEARCH("Time: ",F8)+6,SEARCH(" ",F8,SEARCH("Time: ",F8)+7)-SEARCH("Time: ",F8)-6)*1,"") -> 0.00097107887
A9: Buttons: (1,3) (1,2) (0,1,2,3) | E9: =IF(LEFT(A9,7)="SOLVED!",1,"") | F9: =IF(E9=1,RIGHT(A9,LEN(A9)-26),"") | G9: =IF(E9=1,LEFT(F9,SEARCH(" ",F9))*1,"") | H9: =IF(E9=1,MID(F9,SEARCH("line ",F9)+5,SEARCH(" ",F9,SEARCH("line ",F9)+6)-SEARCH("line ",F9)-5)*1,"") | I9: =IF(E9=1,MID(F9,SEARCH("Time: ",F9)+6,SEARCH(" ",F9,SEARCH("Time: ",F9)+7)-SEARCH("Time: ",F9)-6)*1,"")
A10: Third segment: {19,46,28,37} | E10: =IF(LEFT(A10,7)="SOLVED!",1,"") | F10: =IF(E10=1,RIGHT(A10,LEN(A10)-26),"") | G10: =IF(E10=1,LEFT(F10,SEARCH(" ",F10))*1,"") | H10: =IF(E10=1,MID(F10,SEARCH("line ",F10)+5,SEARCH(" ",F10,SEARCH("line ",F10)+6)-SEARCH("line ",F10)-5)*1,"") | I10: =IF(E10=1,MID(F10,SEARCH("Time: ",F10)+6,SEARCH(" ",F10,SEARCH("Time: ",F10)+7)-SEARCH("Time: ",F10)-6)*1,"")
E11: =IF(LEFT(A11,7)="SOLVED!",1,"") | F11: =IF(E11=1,RIGHT(A11,LEN(A11)-26),"") | G11: =IF(E11=1,LEFT(F11,SEARCH(" ",F11))*1,"") | H11: =IF(E11=1,MID(F11,SEARCH("line ",F11)+5,SEARCH(" ",F11,SEARCH("line ",F11)+6)-SEARCH("line ",F11)-5)*1,"") | I11: =IF(E11=1,MID(F11,SEARCH("Time: ",F11)+6,SEARCH(" ",F11,SEARCH("Time: ",F11)+7)-SEARCH("Time: ",F11)-6)*1,"")
A12: SOLVED! New button count: 46.0 for line 2 (Time: 0.00038504600524902344 seconds) | E12: =IF(LEFT(A12,7)="SOLVED!",1,"") -> 1 | F12: =IF(E12=1,RIGHT(A12,LEN(A12)-26),"") -> 46.0 for line 2 (Time: 0.00038504600524902344 seconds) | G12: =IF(E12=1,LEFT(F12,SEARCH(" ",F12))*1,"") -> 46 | H12: =IF(E12=1,MID(F12,SEARCH("line ",F12)+5,SEARCH(" ",F12,SEARCH("line ",F12)+6)-SEARCH("line ",F12)-5)*1,"") -> 2 | I12: =IF(E12=1,MID(F12,SEARCH("Time: ",F12)+6,SEARCH(" ",F12,SEARCH("Time: ",F12)+7)-SEARCH("Time: ",F12)-6)*1,"") -> 0.00038504601
A13: Buttons: (2,3) (0,5) (0,3) (1,3,5) (1,3) (1,2,3) (0,2,3,4) (0,1,3) | E13: =IF(LEFT(A13,7)="SOLVED!",1,"") | F13: =IF(E13=1,RIGHT(A13,LEN(A13)-26),"") | G13: =IF(E13=1,LEFT(F13,SEARCH(" ",F13))*1,"") | H13: =IF(E13=1,MID(F13,SEARCH("line ",F13)+5,SEARCH(" ",F13,SEARCH("line ",F13)+6)-SEARCH("line ",F13)-5)*1,"") | I13: =IF(E13=1,MID(F13,SEARCH("Time: ",F13)+6,SEARCH(" ",F13,SEARCH("Time: ",F13)+7)-SEARCH("Time: ",F13)-6)*1,"")
A14: Third segment: {43,26,17,46,15,25} | E14: =IF(LEFT(A14,7)="SOLVED!",1,"") | F14: =IF(E14=1,RIGHT(A14,LEN(A14)-26),"") | G14: =IF(E14=1,LEFT(F14,SEARCH(" ",F14))*1,"") | H14: =IF(E14=1,MID(F14,SEARCH("line ",F14)+5,SEARCH(" ",F14,SEARCH("line ",F14)+6)-SEARCH("line ",F14)-5)*1,"") | I14: =IF(E14=1,MID(F14,SEARCH("Time: ",F14)+6,SEARCH(" ",F14,SEARCH("Time: ",F14)+7)-SEARCH("Time: ",F14)-6)*1,"")
E15: =IF(LEFT(A15,7)="SOLVED!",1,"") | F15: =IF(E15=1,RIGHT(A15,LEN(A15)-26),"") | G15: =IF(E15=1,LEFT(F15,SEARCH(" ",F15))*1,"") | H15: =IF(E15=1,MID(F15,SEARCH("line ",F15)+5,SEARCH(" ",F15,SEARCH("line ",F15)+6)-SEARCH("line ",F15)-5)*1,"") | I15: =IF(E15=1,MID(F15,SEARCH("Time: ",F15)+6,SEARCH(" ",F15,SEARCH("Time: ",F15)+7)-SEARCH("Time: ",F15)-6)*1,"")
A16: SOLVED! New button count: 58.0 for line 3 (Time: 0.00038814544677734375 seconds) | E16: =IF(LEFT(A16,7)="SOLVED!",1,"") -> 1 | F16: =IF(E16=1,RIGHT(A16,LEN(A16)-26),"") -> 58.0 for line 3 (Time: 0.00038814544677734375 seconds) | G16: =IF(E16=1,LEFT(F16,SEARCH(" ",F16))*1,"") -> 58 | H16: =IF(E16=1,MID(F16,SEARCH("line ",F16)+5,SEARCH(" ",F16,SEARCH("line ",F16)+6)-SEARCH("line ",F16)-5)*1,"") -> 3 | I16: =IF(E16=1,MID(F16,SEARCH("Time: ",F16)+6,SEARCH(" ",F16,SEARCH("Time: ",F16)+7)-SEARCH("Time: ",F16)-6)*1,"") -> 0.00038814545
A17: Buttons: (0,1,2,3,5,7,8) (0,1,2,3,4,6,7,8) (1) (0,2,3,4,5,6,7) (0,1,7) (0,2,3,5) (3,8) (1,6) (0,1,2,4) (0,1,6,7,8) | E17: =IF(LEFT(A17,7)="SOLVED!",1,"") | F17: =IF(E17=1,RIGHT(A17,LEN(A17)-26),"") | G17: =IF(E17=1,LEFT(F17,SEARCH(" ",F17))*1,"") | H17: =IF(E17=1,MID(F17,SEARCH("line ",F17)+5,SEARCH(" ",F17,SEARCH("line ",F17)+6)-SEARCH("line ",F17)-5)*1,"") | I17: =IF(E17=1,MID(F17,SEARCH("Time: ",F17)+6,SEARCH(" ",F17,SEARCH("Time: ",F17)+7)-SEARCH("Time: ",F17)-6)*1,"")
A18: Third segment: {61,67,34,31,28,23,53,50,24} | E18: =IF(LEFT(A18,7)="SOLVED!",1,"") | F18: =IF(E18=1,RIGHT(A18,LEN(A18)-26),"") | G18: =IF(E18=1,LEFT(F18,SEARCH(" ",F18))*1,"") | H18: =IF(E18=1,MID(F18,SEARCH("line ",F18)+5,SEARCH(" ",F18,SEARCH("line ",F18)+6)-SEARCH("line ",F18)-5)*1,"") | I18: =IF(E18=1,MID(F18,SEARCH("Time: ",F18)+6,SEARCH(" ",F18,SEARCH("Time: ",F18)+7)-SEARCH("Time: ",F18)-6)*1,"")
E19: =IF(LEFT(A19,7)="SOLVED!",1,"") | F19: =IF(E19=1,RIGHT(A19,LEN(A19)-26),"") | G19: =IF(E19=1,LEFT(F19,SEARCH(" ",F19))*1,"") | H19: =IF(E19=1,MID(F19,SEARCH("line ",F19)+5,SEARCH(" ",F19,SEARCH("line ",F19)+6)-SEARCH("line ",F19)-5)*1,"") | I19: =IF(E19=1,MID(F19,SEARCH("Time: ",F19)+6,SEARCH(" ",F19,SEARCH("Time: ",F19)+7)-SEARCH("Time: ",F19)-6)*1,"")
A20: SOLVED! New button count: 92.0 for line 4 (Time: 0.00038909912109375 seconds) | E20: =IF(LEFT(A20,7)="SOLVED!",1,"") -> 1 | F20: =IF(E20=1,RIGHT(A20,LEN(A20)-26),"") -> 92.0 for line 4 (Time: 0.00038909912109375 seconds) | G20: =IF(E20=1,LEFT(F20,SEARCH(" ",F20))*1,"") -> 92 | H20: =IF(E20=1,MID(F20,SEARCH("line ",F20)+5,SEARCH(" ",F20,SEARCH("line ",F20)+6)-SEARCH("line ",F20)-5)*1,"") -> 4 | I20: =IF(E20=1,MID(F20,SEARCH("Time: ",F20)+6,SEARCH(" ",F20,SEARCH("Time: ",F20)+7)-SEARCH("Time: ",F20)-6)*1,"") -> 0.00038909912
A21: Buttons: (0,1,2,4,6,7,8,9) (6) (3,4,5,7,8) (3,4,7) (2,5) (2,4,7,9) (2,4,5,7) (1) (3,5,6,9) (0,5,7,9) (0,1,3,4,7,9) | E21: =IF(LEFT(A21,7)="SOLVED!",1,"") | F21: =IF(E21=1,RIGHT(A21,LEN(A21)-26),"") | G21: =IF(E21=1,LEFT(F21,SEARCH(" ",F21))*1,"") | H21: =IF(E21=1,MID(F21,SEARCH("line ",F21)+5,SEARCH(" ",F21,SEARCH("line ",F21)+6)-SEARCH("line ",F21)-5)*1,"") | I21: =IF(E21=1,MID(F21,SEARCH("Time: ",F21)+6,SEARCH(" ",F21,SEARCH("Time: ",F21)+7)-SEARCH("Time: ",F21)-6)*1,"")
A22: Third segment: {44,47,57,42,69,46,40,78,21,69} | E22: =IF(LEFT(A22,7)="SOLVED!",1,"") | F22: =IF(E22=1,RIGHT(A22,LEN(A22)-26),"") | G22: =IF(E22=1,LEFT(F22,SEARCH(" ",F22))*1,"") | H22: =IF(E22=1,MID(F22,SEARCH("line ",F22)+5,SEARCH(" ",F22,SEARCH("line ",F22)+6)-SEARCH("line ",F22)-5)*1,"") | I22: =IF(E22=1,MID(F22,SEARCH("Time: ",F22)+6,SEARCH(" ",F22,SEARCH("Time: ",F22)+7)-SEARCH("Time: ",F22)-6)*1,"")
E23: =IF(LEFT(A23,7)="SOLVED!",1,"") | F23: =IF(E23=1,RIGHT(A23,LEN(A23)-26),"") | G23: =IF(E23=1,LEFT(F23,SEARCH(" ",F23))*1,"") | H23: =IF(E23=1,MID(F23,SEARCH("line ",F23)+5,SEARCH(" ",F23,SEARCH("line ",F23)+6)-SEARCH("line ",F23)-5)*1,"") | I23: =IF(E23=1,MID(F23,SEARCH("Time: ",F23)+6,SEARCH(" ",F23,SEARCH("Time: ",F23)+7)-SEARCH("Time: ",F23)-6)*1,"")
A24: SOLVED! New button count: 126.0 for line 5 (Time: 0.0003719329833984375 seconds) | E24: =IF(LEFT(A24,7)="SOLVED!",1,"") -> 1 | F24: =IF(E24=1,RIGHT(A24,LEN(A24)-26),"") -> 126.0 for line 5 (Time: 0.0003719329833984375 seconds) | G24: =IF(E24=1,LEFT(F24,SEARCH(" ",F24))*1,"") -> 126 | H24: =IF(E24=1,MID(F24,SEARCH("line ",F24)+5,SEARCH(" ",F24,SEARCH("line ",F24)+6)-SEARCH("line ",F24)-5)*1,"") -> 5 | I24: =IF(E24=1,MID(F24,SEARCH("Time: ",F24)+6,SEARCH(" ",F24,SEARCH("Time: ",F24)+7)-SEARCH("Time: ",F24)-6)*1,"") -> 0.00037193298
A25: Buttons: (1,2,3,4,5,7) (0,1,2,4,5,6) (0,2,5,6) (0,2,3,4,6,7) (0,1,2,3,5,6,7) (0,1,2,3,4,5,7) | E25: =IF(LEFT(A25,7)="SOLVED!",1,"") | F25: =IF(E25=1,RIGHT(A25,LEN(A25)-26),"") | G25: =IF(E25=1,LEFT(F25,SEARCH(" ",F25))*1,"") | H25: =IF(E25=1,MID(F25,SEARCH("line ",F25)+5,SEARCH(" ",F25,SEARCH("line ",F25)+6)-SEARCH("line ",F25)-5)*1,"") | I25: =IF(E25=1,MID(F25,SEARCH("Time: ",F25)+6,SEARCH(" ",F25,SEARCH("Time: ",F25)+7)-SEARCH("Time: ",F25)-6)*1,"")
A26: Third segment: {36,19,43,20,30,31,36,20} | E26: =IF(LEFT(A26,7)="SOLVED!",1,"") | F26: =IF(E26=1,RIGHT(A26,LEN(A26)-26),"") | G26: =IF(E26=1,LEFT(F26,SEARCH(" ",F26))*1,"") | H26: =IF(E26=1,MID(F26,SEARCH("line ",F26)+5,SEARCH(" ",F26,SEARCH("line ",F26)+6)-SEARCH("line ",F26)-5)*1,"") | I26: =IF(E26=1,MID(F26,SEARCH("Time: ",F26)+6,SEARCH(" ",F26,SEARCH("Time: ",F26)+7)-SEARCH("Time: ",F26)-6)*1,"")
E27: =IF(LEFT(A27,7)="SOLVED!",1,"") | F27: =IF(E27=1,RIGHT(A27,LEN(A27)-26),"") | G27: =IF(E27=1,LEFT(F27,SEARCH(" ",F27))*1,"") | H27: =IF(E27=1,MID(F27,SEARCH("line ",F27)+5,SEARCH(" ",F27,SEARCH("line ",F27)+6)-SEARCH("line ",F27)-5)*1,"") | I27: =IF(E27=1,MID(F27,SEARCH("Time: ",F27)+6,SEARCH(" ",F27,SEARCH("Time: ",F27)+7)-SEARCH("Time: ",F27)-6)*1,"")
A28: SOLVED! New button count: 43.0 for line 6 (Time: 0.0003421306610107422 seconds) | E28: =IF(LEFT(A28,7)="SOLVED!",1,"") -> 1 | F28: =IF(E28=1,RIGHT(A28,LEN(A28)-26),"") -> 43.0 for line 6 (Time: 0.0003421306610107422 seconds) | G28: =IF(E28=1,LEFT(F28,SEARCH(" ",F28))*1,"") -> 43 | H28: =IF(E28=1,MID(F28,SEARCH("line ",F28)+5,SEARCH(" ",F28,SEARCH("line ",F28)+6)-SEARCH("line ",F28)-5)*1,"") -> 6 | I28: =IF(E28=1,MID(F28,SEARCH("Time: ",F28)+6,SEARCH(" ",F28,SEARCH("Time: ",F28)+7)-SEARCH("Time: ",F28)-6)*1,"") -> 0.00034213066
A29: Buttons: (0,1,2) (1,4) (0,3) | E29: =IF(LEFT(A29,7)="SOLVED!",1,"") | F29: =IF(E29=1,RIGHT(A29,LEN(A29)-26),"") | G29: =IF(E29=1,LEFT(F29,SEARCH(" ",F29))*1,"") | H29: =IF(E29=1,MID(F29,SEARCH("line ",F29)+5,SEARCH(" ",F29,SEARCH("line ",F29)+6)-SEARCH("line ",F29)-5)*1,"") | I29: =IF(E29=1,MID(F29,SEARCH("Time: ",F29)+6,SEARCH(" ",F29,SEARCH("Time: ",F29)+7)-SEARCH("Time: ",F29)-6)*1,"")
A30: Third segment: {18,30,13,5,17} | E30: =IF(LEFT(A30,7)="SOLVED!",1,"") | F30: =IF(E30=1,RIGHT(A30,LEN(A30)-26),"") | G30: =IF(E30=1,LEFT(F30,SEARCH(" ",F30))*1,"") | H30: =IF(E30=1,MID(F30,SEARCH("line ",F30)+5,SEARCH(" ",F30,SEARCH("line ",F30)+6)-SEARCH("line ",F30)-5)*1,"") | I30: =IF(E30=1,MID(F30,SEARCH("Time: ",F30)+6,SEARCH(" ",F30,SEARCH("Time: ",F30)+7)-SEARCH("Time: ",F30)-6)*1,"")
E31: =IF(LEFT(A31,7)="SOLVED!",1,"") | F31: =IF(E31=1,RIGHT(A31,LEN(A31)-26),"") | G31: =IF(E31=1,LEFT(F31,SEARCH(" ",F31))*1,"") | H31: =IF(E31=1,MID(F31,SEARCH("line ",F31)+5,SEARCH(" ",F31,SEARCH("line ",F31)+6)-SEARCH("line ",F31)-5)*1,"") | I31: =IF(E31=1,MID(F31,SEARCH("Time: ",F31)+6,SEARCH(" ",F31,SEARCH("Time: ",F31)+7)-SEARCH("Time: ",F31)-6)*1,"")
A32: SOLVED! New button count: 35.0 for line 7 (Time: 0.0003120899200439453 seconds) | E32: =IF(LEFT(A32,7)="SOLVED!",1,"") -> 1 | F32: =IF(E32=1,RIGHT(A32,LEN(A32)-26),"") -> 35.0 for line 7 (Time: 0.0003120899200439453 seconds) | G32: =IF(E32=1,LEFT(F32,SEARCH(" ",F32))*1,"") -> 35 | H32: =IF(E32=1,MID(F32,SEARCH("line ",F32)+5,SEARCH(" ",F32,SEARCH("line ",F32)+6)-SEARCH("line ",F32)-5)*1,"") -> 7 | I32: =IF(E32=1,MID(F32,SEARCH("Time: ",F32)+6,SEARCH(" ",F32,SEARCH("Time: ",F32)+7)-SEARCH("Time: ",F32)-6)*1,"") -> 0.00031208992
A33: Buttons: (2,4,6,7) (0,1,2,3,5,7) (2) (1,7) (0,2,3,5) (0,1,3,4,5,7) (3,5,6,7) | E33: =IF(LEFT(A33,7)="SOLVED!",1,"") | F33: =IF(E33=1,RIGHT(A33,LEN(A33)-26),"") | G33: =IF(E33=1,LEFT(F33,SEARCH(" ",F33))*1,"") | H33: =IF(E33=1,MID(F33,SEARCH("line ",F33)+5,SEARCH(" ",F33,SEARCH("line ",F33)+6)-SEARCH("line ",F33)-5)*1,"") | I33: =IF(E33=1,MID(F33,SEARCH("Time: ",F33)+6,SEARCH(" ",F33,SEARCH("Time: ",F33)+7)-SEARCH("Time: ",F33)-6)*1,"")
A34: Third segment: {42,135,61,53,17,53,21,156} | E34: =IF(LEFT(A34,7)="SOLVED!",1,"") | F34: =IF(E34=1,RIGHT(A34,LEN(A34)-26),"") | G34: =IF(E34=1,LEFT(F34,SEARCH(" ",F34))*1,"") | H34: =IF(E34=1,MID(F34,SEARCH("line ",F34)+5,SEARCH(" ",F34,SEARCH("line ",F34)+6)-SEARCH("line ",F34)-5)*1,"") | I34: =IF(E34=1,MID(F34,SEARCH("Time: ",F34)+6,SEARCH(" ",F34,SEARCH("Time: ",F34)+7)-SEARCH("Time: ",F34)-6)*1,"")
E35: =IF(LEFT(A35,7)="SOLVED!",1,"") | F35: =IF(E35=1,RIGHT(A35,LEN(A35)-26),"") | G35: =IF(E35=1,LEFT(F35,SEARCH(" ",F35))*1,"") | H35: =IF(E35=1,MID(F35,SEARCH("line ",F35)+5,SEARCH(" ",F35,SEARCH("line ",F35)+6)-SEARCH("line ",F35)-5)*1,"") | I35: =IF(E35=1,MID(F35,SEARCH("Time: ",F35)+6,SEARCH(" ",F35,SEARCH("Time: ",F35)+7)-SEARCH("Time: ",F35)-6)*1,"")
A36: SOLVED! New button count: 172.0 for line 8 (Time: 0.0003368854522705078 seconds) | E36: =IF(LEFT(A36,7)="SOLVED!",1,"") -> 1 | F36: =IF(E36=1,RIGHT(A36,LEN(A36)-26),"") -> 172.0 for line 8 (Time: 0.0003368854522705078 seconds) | G36: =IF(E36=1,LEFT(F36,SEARCH(" ",F36))*1,"") -> 172 | H36: =IF(E36=1,MID(F36,SEARCH("line ",F36)+5,SEARCH(" ",F36,SEARCH("line ",F36)+6)-SEARCH("line ",F36)-5)*1,"") -> 8 | I36: =IF(E36=1,MID(F36,SEARCH("Time: ",F36)+6,SEARCH(" ",F36,SEARCH("Time: ",F36)+7)-SEARCH("Time: ",F36)-6)*1,"") -> 0.00033688545
A37: Buttons: (3,4,5,6,7,8) (0,1,4,6) (0,3,5,6,7) (0,2,7,8) (0,2,4,6,8) (0,6,7,8) (1,2,3,5,6) (0,2,3) (6,7) (1,2,6,7) (0,1,2,5,6,7,8) | E37: =IF(LEFT(A37,7)="SOLVED!",1,"") | F37: =IF(E37=1,RIGHT(A37,LEN(A37)-26),"") | G37: =IF(E37=1,LEFT(F37,SEARCH(" ",F37))*1,"") | H37: =IF(E37=1,MID(F37,SEARCH("line ",F37)+5,SEARCH(" ",F37,SEARCH("line ",F37)+6)-SEARCH("line ",F37)-5)*1,"") | I37: =IF(E37=1,MID(F37,SEARCH("Time: ",F37)+6,SEARCH(" ",F37,SEARCH("Time: ",F37)+7)-SEARCH("Time: ",F37)-6)*1,"")
A38: Third segment: {71,51,85,42,27,59,108,93,75} | E38: =IF(LEFT(A38,7)="SOLVED!",1,"") | F38: =IF(E38=1,RIGHT(A38,LEN(A38)-26),"") | G38: =IF(E38=1,LEFT(F38,SEARCH(" ",F38))*1,"") | H38: =IF(E38=1,MID(F38,SEARCH("line ",F38)+5,SEARCH(" ",F38,SEARCH("line ",F38)+6)-SEARCH("line ",F38)-5)*1,"") | I38: =IF(E38=1,MID(F38,SEARCH("Time: ",F38)+6,SEARCH(" ",F38,SEARCH("Time: ",F38)+7)-SEARCH("Time: ",F38)-6)*1,"")
E39: =IF(LEFT(A39,7)="SOLVED!",1,"") | F39: =IF(E39=1,RIGHT(A39,LEN(A39)-26),"") | G39: =IF(E39=1,LEFT(F39,SEARCH(" ",F39))*1,"") | H39: =IF(E39=1,MID(F39,SEARCH("line ",F39)+5,SEARCH(" ",F39,SEARCH("line ",F39)+6)-SEARCH("line ",F39)-5)*1,"") | I39: =IF(E39=1,MID(F39,SEARCH("Time: ",F39)+6,SEARCH(" ",F39,SEARCH("Time: ",F39)+7)-SEARCH("Time: ",F39)-6)*1,"")
A40: SOLVED! New button count: 128.0 for line 9 (Time: 0.0008509159088134766 seconds) | E40: =IF(LEFT(A40,7)="SOLVED!",1,"") -> 1 | F40: =IF(E40=1,RIGHT(A40,LEN(A40)-26),"") -> 128.0 for line 9 (Time: 0.0008509159088134766 seconds) | G40: =IF(E40=1,LEFT(F40,SEARCH(" ",F40))*1,"") -> 128 | H40: =IF(E40=1,MID(F40,SEARCH("line ",F40)+5,SEARCH(" ",F40,SEARCH("line ",F40)+6)-SEARCH("line ",F40)-5)*1,"") -> 9 | I40: =IF(E40=1,MID(F40,SEARCH("Time: ",F40)+6,SEARCH(" ",F40,SEARCH("Time: ",F40)+7)-SEARCH("Time: ",F40)-6)*1,"") -> 0.00085091591
...

Sheet By Line
B1: Ruby | C1: Ruby | D1: Python | E1: Python
A2: Line | B2: Count | C2: Seconds Taken | D2: Count | E2: Seconds Taken | F2: Line Diff | J2: Ruby | K2: Python
A3: 0 | B3: =INDEX('Raw Logs'!$G$3:$G$741,MATCH('By Line'!$A3,'Raw Logs'!$H$3:$H$741,0)) -> 45 | C3: =INDEX('Raw Logs'!$I$3:$I$741,MATCH('By Line'!$A3,'Raw Logs'!$H$3:$H$741,0)) -> 0.07 | D3: =INDEX('Raw Logs - Python'!$G$3:$G$800,MATCH('By Line'!$A3,'Raw Logs - Python'!$H$3:$H$800,0)) -> 45 | E3: =INDEX('Raw Logs - Python'!$I$3:$I$800,MATCH('By Line'!$A3,'Raw Logs - Python'!$H$3:$H$800,0)) -> 0.00097489357 | F3: =IF(B3-D3=0, "","ERROR") | I3: Current Total: | J3: =SUMIFS($B$3:$B$201,$B$3:$B$201, "<>#N/A" ) -> 19648 | K3: =SUMIFS($D$3:$D$201,$D$3:$D$201, "<>#N/A" ) -> 20869
A4: =A3+1 -> 1 | B4: =INDEX('Raw Logs'!$G$3:$G$741,MATCH('By Line'!$A4,'Raw Logs'!$H$3:$H$741,0)) -> 68 | C4: =INDEX('Raw Logs'!$I$3:$I$741,MATCH('By Line'!$A4,'Raw Logs'!$H$3:$H$741,0)) -> 2.23 | D4: =INDEX('Raw Logs - Python'!$G$3:$G$800,MATCH('By Line'!$A4,'Raw Logs - Python'!$H$3:$H$800,0)) -> 68 | E4: =INDEX('Raw Logs - Python'!$I$3:$I$800,MATCH('By Line'!$A4,'Raw Logs - Python'!$H$3:$H$800,0)) -> 0.00097107887 | F4: =IF(B4-D4=0, "","ERROR") | I4: Time Taken: | J4: =SUMIFS($C$3:$C$201,$C$3:$C$201, "<>#N/A" ) -> 771.66 | K4: =SUMIFS($E$3:$E$201,$E$3:$E$201, "<>#N/A" ) -> 0.097425461
A5: =A4+1 -> 2 | B5: =INDEX('Raw Logs'!$G$3:$G$741,MATCH('By Line'!$A5,'Raw Logs'!$H$3:$H$741,0)) -> 46 | C5: =INDEX('Raw Logs'!$I$3:$I$741,MATCH('By Line'!$A5,'Raw Logs'!$H$3:$H$741,0)) -> 0 | D5: =INDEX('Raw Logs - Python'!$G$3:$G$800,MATCH('By Line'!$A5,'Raw Logs - Python'!$H$3:$H$800,0)) -> 46 | E5: =INDEX('Raw Logs - Python'!$I$3:$I$800,MATCH('By Line'!$A5,'Raw Logs - Python'!$H$3:$H$800,0)) -> 0.00038504601 | F5: =IF(B5-D5=0, "","ERROR")
A6: =A5+1 -> 3 | B6: =INDEX('Raw Logs'!$G$3:$G$741,MATCH('By Line'!$A6,'Raw Logs'!$H$3:$H$741,0)) -> 58 | C6: =INDEX('Raw Logs'!$I$3:$I$741,MATCH('By Line'!$A6,'Raw Logs'!$H$3:$H$741,0)) -> 0.01 | D6: =INDEX('Raw Logs - Python'!$G$3:$G$800,MATCH('By Line'!$A6,'Raw Logs - Python'!$H$3:$H$800,0)) -> 58 | E6: =INDEX('Raw Logs - Python'!$I$3:$I$800,MATCH('By Line'!$A6,'Raw Logs - Python'!$H$3:$H$800,0)) -> 0.00038814545 | F6: =IF(B6-D6=0, "","ERROR")
A7: =A6+1 -> 4 | B7: =INDEX('Raw Logs'!$G$3:$G$741,MATCH('By Line'!$A7,'Raw Logs'!$H$3:$H$741,0)) -> 92 | C7: =INDEX('Raw Logs'!$I$3:$I$741,MATCH('By Line'!$A7,'Raw Logs'!$H$3:$H$741,0)) -> 0.13 | D7: =INDEX('Raw Logs - Python'!$G$3:$G$800,MATCH('By Line'!$A7,'Raw Logs - Python'!$H$3:$H$800,0)) -> 92 | E7: =INDEX('Raw Logs - Python'!$I$3:$I$800,MATCH('By Line'!$A7,'Raw Logs - Python'!$H$3:$H$800,0)) -> 0.00038909912 | F7: =IF(B7-D7=0, "","ERROR")
A8: =A7+1 -> 5 | B8: =INDEX('Raw Logs'!$G$3:$G$741,MATCH('By Line'!$A8,'Raw Logs'!$H$3:$H$741,0)) -> 126 | C8: =INDEX('Raw Logs'!$I$3:$I$741,MATCH('By Line'!$A8,'Raw Logs'!$H$3:$H$741,0)) -> 0.21 | D8: =INDEX('Raw Logs - Python'!$G$3:$G$800,MATCH('By Line'!$A8,'Raw Logs - Python'!$H$3:$H$800,0)) -> 126 | E8: =INDEX('Raw Logs - Python'!$I$3:$I$800,MATCH('By Line'!$A8,'Raw Logs - Python'!$H$3:$H$800,0)) -> 0.00037193298 | F8: =IF(B8-D8=0, "","ERROR")
A9: =A8+1 -> 6 | B9: =INDEX('Raw Logs'!$G$3:$G$741,MATCH('By Line'!$A9,'Raw Logs'!$H$3:$H$741,0)) -> 43 | C9: =INDEX('Raw Logs'!$I$3:$I$741,MATCH('By Line'!$A9,'Raw Logs'!$H$3:$H$741,0)) -> 0.04 | D9: =INDEX('Raw Logs - Python'!$G$3:$G$800,MATCH('By Line'!$A9,'Raw Logs - Python'!$H$3:$H$800,0)) -> 43 | E9: =INDEX('Raw Logs - Python'!$I$3:$I$800,MATCH('By Line'!$A9,'Raw Logs - Python'!$H$3:$H$800,0)) -> 0.00034213066 | F9: =IF(B9-D9=0, "","ERROR")
A10: =A9+1 -> 7 | B10: =INDEX('Raw Logs'!$G$3:$G$741,MATCH('By Line'!$A10,'Raw Logs'!$H$3:$H$741,0)) -> 35 | C10: =INDEX('Raw Logs'!$I$3:$I$741,MATCH('By Line'!$A10,'Raw Logs'!$H$3:$H$741,0)) -> 0 | D10: =INDEX('Raw Logs - Python'!$G$3:$G$800,MATCH('By Line'!$A10,'Raw Logs - Python'!$H$3:$H$800,0)) -> 35 | E10: =INDEX('Raw Logs - Python'!$I$3:$I$800,MATCH('By Line'!$A10,'Raw Logs - Python'!$H$3:$H$800,0)) -> 0.00031208992 | F10: =IF(B10-D10=0, "","ERROR")
A11: =A10+1 -> 8 | B11: =INDEX('Raw Logs'!$G$3:$G$741,MATCH('By Line'!$A11,'Raw Logs'!$H$3:$H$741,0)) -> 172 | C11: =INDEX('Raw Logs'!$I$3:$I$741,MATCH('By Line'!$A11,'Raw Logs'!$H$3:$H$741,0)) -> 0.02 | D11: =INDEX('Raw Logs - Python'!$G$3:$G$800,MATCH('By Line'!$A11,'Raw Logs - Python'!$H$3:$H$800,0)) -> 172 | E11: =INDEX('Raw Logs - Python'!$I$3:$I$800,MATCH('By Line'!$A11,'Raw Logs - Python'!$H$3:$H$800,0)) -> 0.00033688545 | F11: =IF(B11-D11=0, "","ERROR")
A12: =A11+1 -> 9 | B12: =INDEX('Raw Logs'!$G$3:$G$741,MATCH('By Line'!$A12,'Raw Logs'!$H$3:$H$741,0)) -> 128 | C12: =INDEX('Raw Logs'!$I$3:$I$741,MATCH('By Line'!$A12,'Raw Logs'!$H$3:$H$741,0)) -> 19.84 | D12: =INDEX('Raw Logs - Python'!$G$3:$G$800,MATCH('By Line'!$A12,'Raw Logs - Python'!$H$3:$H$800,0)) -> 128 | E12: =INDEX('Raw Logs - Python'!$I$3:$I$800,MATCH('By Line'!$A12,'Raw Logs - Python'!$H$3:$H$800,0)) -> 0.00085091591 | F12: =IF(B12-D12=0, "","ERROR")
A13: =A12+1 -> 10 | B13: =INDEX('Raw Logs'!$G$3:$G$741,MATCH('By Line'!$A13,'Raw Logs'!$H$3:$H$741,0)) -> 202 | C13: =INDEX('Raw Logs'!$I$3:$I$741,MATCH('By Line'!$A13,'Raw Logs'!$H$3:$H$741,0)) -> 0.38 | D13: =INDEX('Raw Logs - Python'!$G$3:$G$800,MATCH('By Line'!$A13,'Raw Logs - Python'!$H$3:$H$800,0)) -> 202 | E13: =INDEX('Raw Logs - Python'!$I$3:$I$800,MATCH('By Line'!$A13,'Raw Logs - Python'!$H$3:$H$800,0)) -> 0.00037813187 | F13: =IF(B13-D13=0, "","ERROR")
A14: =A13+1 -> 11 | B14: =INDEX('Raw Logs'!$G$3:$G$741,MATCH('By Line'!$A14,'Raw Logs'!$H$3:$H$741,0)) -> 99 | C14: =INDEX('Raw Logs'!$I$3:$I$741,MATCH('By Line'!$A14,'Raw Logs'!$H$3:$H$741,0)) -> 24.49 | D14: =INDEX('Raw Logs - Python'!$G$3:$G$800,MATCH('By Line'!$A14,'Raw Logs - Python'!$H$3:$H$800,0)) -> 99 | E14: =INDEX('Raw Logs - Python'!$I$3:$I$800,MATCH('By Line'!$A14,'Raw Logs - Python'!$H$3:$H$800,0)) -> 0.00095105171 | F14: =IF(B14-D14=0, "","ERROR")
A15: =A14+1 -> 12 | B15: =INDEX('Raw Logs'!$G$3:$G$741,MATCH('By Line'!$A15,'Raw Logs'!$H$3:$H$741,0)) -> 204 | C15: =INDEX('Raw Logs'!$I$3:$I$741,MATCH('By Line'!$A15,'Raw Logs'!$H$3:$H$741,0)) -> 12.51 | D15: =INDEX('Raw Logs - Python'!$G$3:$G$800,MATCH('By Line'!$A15,'Raw Logs - Python'!$H$3:$H$800,0)) -> 204 | E15: =INDEX('Raw Logs - Python'!$I$3:$I$800,MATCH('By Line'!$A15,'Raw Logs - Python'!$H$3:$H$800,0)) -> 0.00052213669 | F15: =IF(B15-D15=0, "","ERROR")
A16: =A15+1 -> 13 | B16: =INDEX('Raw Logs'!$G$3:$G$741,MATCH('By Line'!$A16,'Raw Logs'!$H$3:$H$741,0)) -> #N/A | C16: =INDEX('Raw Logs'!$I$3:$I$741,MATCH('By Line'!$A16,'Raw Logs'!$H$3:$H$741,0)) -> #N/A | D16: =INDEX('Raw Logs - Python'!$G$3:$G$800,MATCH('By Line'!$A16,'Raw Logs - Python'!$H$3:$H$800,0)) -> 114 | E16: =INDEX('Raw Logs - Python'!$I$3:$I$800,MATCH('By Line'!$A16,'Raw Logs - Python'!$H$3:$H$800,0)) -> 0.00087690353 | F16: =IF(B16-D16=0, "","ERROR") -> #N/A
... A201: =A200+1 -> 198 | B201: =INDEX('Raw Logs'!$G$3:$G$741,MATCH('By Line'!$A201,'Raw Logs'!$H$3:$H$741,0)) -> 256 | C201: =INDEX('Raw Logs'!$I$3:$I$741,MATCH('By Line'!$A201,'Raw Logs'!$H$3:$H$741,0)) -> 0.02 | D201: =INDEX('Raw Logs - Python'!$G$3:$G$800,MATCH('By Line'!$A201,'Raw Logs - Python'!$H$3:$H$800,0)) -> 256 | E201: =INDEX('Raw Logs - Python'!$I$3:$I$800,MATCH('By Line'!$A201,'Raw Logs - Python'!$H$3:$H$800,0)) -> 0.0003452301 | F201: =IF(B201-D201=0, "","ERROR")

Sheet 121
A2: Third segment: {88,54,61,53,46,58,67,51,88,33}
B3: Count | C3: PRESSES | E3: 0 | F3: 1 | G3: 2 | H3: 3 | I3: 4 | J3: 5 | K3: 6 | L3: 7 | M3: 8 | N3: 9 | P3: 0 | Q3: 1 | R3: 2 | S3: 3 | T3: 4 | U3: 5 | V3: 6 | W3: 7 | X3: 8 | Y3: 9
A4: (0,1,2,4,5,7,8,9) | B4: =SUM(D4:O4) -> 8 | C4: 10 | E4: 1 | F4: 1 | G4: 1 | I4: 1 | J4: 1 | L4: 1 | M4: 1 | N4: 1 | P4: =$C4*E4 -> 10 | Q4: =$C4*F4 -> 10 | R4: =$C4*G4 -> 10 | S4: =$C4*H4 -> 0 | T4: =$C4*I4 -> 10 | U4: =$C4*J4 -> 10 | V4: =$C4*K4 -> 0 | W4: =$C4*L4 -> 10 | ... Y4: =$C4*N4 -> 10
A5: (0,2,3,4,6,7,8,9) | B5: =SUM(D5:O5) -> 8 | C5: 8 | E5: 1 | G5: 1 | H5: 1 | I5: 1 | K5: 1 | L5: 1 | M5: 1 | N5: 1 | P5: =$C5*E5 -> 8 | Q5: =$C5*F5 -> 0 | R5: =$C5*G5 -> 8 | S5: =$C5*H5 -> 8 | T5: =$C5*I5 -> 8 | U5: =$C5*J5 -> 0 | V5: =$C5*K5 -> 8 | W5: =$C5*L5 -> 8 | ... Y5: =$C5*N5 -> 8
A6: (0,1,2,4,5,6,8) | B6: =SUM(D6:O6) -> 7 | C6: 10 | E6: 1 | F6: 1 | G6: 1 | I6: 1 | J6: 1 | K6: 1 | M6: 1 | P6: =$C6*E6 -> 10 | Q6: =$C6*F6 -> 10 | R6: =$C6*G6 -> 10 | S6: =$C6*H6 -> 0 | T6: =$C6*I6 -> 10 | U6: =$C6*J6 -> 10 | V6: =$C6*K6 -> 10 | W6: =$C6*L6 -> 0 | ... Y6: =$C6*N6 -> 0
A7: (0,1,2,3,6,7,8) | B7: =SUM(D7:O7) -> 7 | C7: 7 | E7: 1 | F7: 1 | G7: 1 | H7: 1 | K7: 1 | L7: 1 | M7: 1 | P7: =$C7*E7 -> 7 | Q7: =$C7*F7 -> 7 | R7: =$C7*G7 -> 7 | S7: =$C7*H7 -> 7 | T7: =$C7*I7 -> 0 | U7: =$C7*J7 -> 0 | V7: =$C7*K7 -> 7 | W7: =$C7*L7 -> 7 | ... Y7: =$C7*N7 -> 0
A8: (0,2,3,6,7,9) | B8: =SUM(D8:O8) -> 6 | E8: 1 | G8: 1 | H8: 1 | K8: 1 | L8: 1 | N8: 1 | P8: =$C8*E8 -> 0 | Q8: =$C8*F8 -> 0 | R8: =$C8*G8 -> 0 | S8: =$C8*H8 -> 0 | T8: =$C8*I8 -> 0 | U8: =$C8*J8 -> 0 | V8: =$C8*K8 -> 0 | W8: =$C8*L8 -> 0 | ... Y8: =$C8*N8 -> 0
A9: (0,1,2,3,4,5,6,8) | B9: =SUM(D9:O9) -> 8 | C9: 5 | E9: 1 | F9: 1 | G9: 1 | H9: 1 | I9: 1 | J9: 1 | K9: 1 | M9: 1 | P9: =$C9*E9 -> 5 | Q9: =$C9*F9 -> 5 | R9: =$C9*G9 -> 5 | S9: =$C9*H9 -> 5 | T9: =$C9*I9 -> 5 | U9: =$C9*J9 -> 5 | V9: =$C9*K9 -> 5 | W9: =$C9*L9 -> 0 | ... Y9: =$C9*N9 -> 0
A10: (0,1,2,3,4,5,8,9) | B10: =SUM(D10:O10) -> 8 | E10: 1 | F10: 1 | G10: 1 | H10: 1 | I10: 1 | J10: 1 | M10: 1 | N10: 1 | P10: =$C10*E10 -> 0 | Q10: =$C10*F10 -> 0 | R10: =$C10*G10 -> 0 | S10: =$C10*H10 -> 0 | T10: =$C10*I10 -> 0 | U10: =$C10*J10 -> 0 | V10: =$C10*K10 -> 0 | W10: =$C10*L10 -> 0 | ... Y10: =$C10*N10 -> 0
A11: (0,1,2,3,6,7,8,9) | B11: =SUM(D11:O11) -> 8 | C11: 10 | E11: 1 | F11: 1 | G11: 1 | H11: 1 | K11: 1 | L11: 1 | M11: 1 | N11: 1 | P11: =$C11*E11 -> 10 | Q11: =$C11*F11 -> 10 | R11: =$C11*G11 -> 10 | S11: =$C11*H11 -> 10 | T11: =$C11*I11 -> 0 | U11: =$C11*J11 -> 0 | V11: =$C11*K11 -> 10 | W11: =$C11*L11 -> 10 | ... Y11: =$C11*N11 -> 10
A12: (0,3,4,6,7,8,9) | B12: =SUM(D12:O12) -> 7 | C12: 5 | E12: 1 | H12: 1 | I12: 1 | K12: 1 | L12: 1 | M12: 1 | N12: 1 | P12: =$C12*E12 -> 5 | Q12: =$C12*F12 -> 0 | R12: =$C12*G12 -> 0 | S12: =$C12*H12 -> 5 | T12: =$C12*I12 -> 5 | U12: =$C12*J12 -> 0 | V12: =$C12*K12 -> 5 | W12: =$C12*L12 -> 5 | ... Y12: =$C12*N12 -> 5
A13: (0,5,8) | B13: =SUM(D13:O13) -> 3 | E13: 1 | J13: 1 | M13: 1 | P13: =$C13*E13 -> 0 | Q13: =$C13*F13 -> 0 | R13: =$C13*G13 -> 0 | S13: =$C13*H13 -> 0 | T13: =$C13*I13 -> 0 | U13: =$C13*J13 -> 0 | V13: =$C13*K13 -> 0 | W13: =$C13*L13 -> 0 | ... Y13: =$C13*N13 -> 0
A14: (0,1,2,3,5,6,7,8) | B14: =SUM(D14:O14) -> 8 | C14: 10 | E14: 1 | F14: 1 | G14: 1 | H14: 1 | J14: 1 | K14: 1 | L14: 1 | M14: 1 | P14: =$C14*E14 -> 10 | Q14: =$C14*F14 -> 10 | R14: =$C14*G14 -> 10 | S14: =$C14*H14 -> 10 | T14: =$C14*I14 -> 0 | U14: =$C14*J14 -> 10 | V14: =$C14*K14 -> 10 | W14: =$C14*L14 -> 10 | ... Y14: =$C14*N14 -> 0
A15: (0,2,5,6,7,8) | B15: =SUM(D15:O15) -> 6 | E15: 1 | G15: 1 | J15: 1 | K15: 1 | L15: 1 | M15: 1 | P15: =$C15*E15 -> 0 | Q15: =$C15*F15 -> 0 | R15: =$C15*G15 -> 0 | S15: =$C15*H15 -> 0 | T15: =$C15*I15 -> 0 | U15: =$C15*J15 -> 0 | V15: =$C15*K15 -> 0 | W15: =$C15*L15 -> 0 | ... Y15: =$C15*N15 -> 0
A16: (1) | B16: =SUM(D16:O16) -> 1 | F16: 1 | P16: =$C16*E16 -> 0 | Q16: =$C16*F16 -> 0 | R16: =$C16*G16 -> 0 | S16: =$C16*H16 -> 0 | T16: =$C16*I16 -> 0 | U16: =$C16*J16 -> 0 | V16: =$C16*K16 -> 0 | W16: =$C16*L16 -> 0 | ... Y16: =$C16*N16 -> 0
A18: Sum | P18: =SUM(P4:P16) -> 65 | Q18: =SUM(Q4:Q16) -> 52 | R18: =SUM(R4:R16) -> 60 | S18: =SUM(S4:S16) -> 45 | T18: =SUM(T4:T16) -> 38 | U18: =SUM(U4:U16) -> 35 | V18: =SUM(V4:V16) -> 55 | W18: =SUM(W4:W16) -> 50 | ... Y18: =SUM(Y4:Y16) -> 33
A19: To go | P19: =P20-P18 -> 23 | Q19: =Q20-Q18 -> 2 | R19: =R20-R18 -> 1 | S19: =S20-S18 -> 8 | T19: =T20-T18 -> 8 | U19: =U20-U18 -> 23 | V19: =V20-V18 -> 12 | W19: =W20-W18 -> 1 | ... Y19: =Y20-Y18 -> 0
A20: Goal | P20: 88 | Q20: 54 | R20: 61 | S20: 53 | T20: 46 | U20: 58 | V20: 67 | W20: 51 | X20: 88 | Y20: 33
